<sdf version='1.10'>
  <world name='default'>
    <physics name='1ms' type='ignored'>
      <max_step_size>0.001</max_step_size>
      <real_time_factor>1</real_time_factor>
      <real_time_update_rate>1000</real_time_update_rate>
    </physics>
    <gravity>0 0 -9.8000000000000007</gravity>
    <magnetic_field>5.5644999999999998e-06 2.2875799999999999e-05 -4.2388400000000002e-05</magnetic_field>
    <atmosphere type='adiabatic'/>
    <scene>
      <ambient>0.400000006 0.400000006 0.400000006 1</ambient>
      <background>0.699999988 0.699999988 0.699999988 1</background>
      <shadows>true</shadows>
    </scene>

    <model name='ground_plane'>
      <static>true</static>
      <link name='link'>
        <collision name='collision'>
          <geometry>
            <plane>
              <normal>0 0 1</normal>
              <size>100 100</size>
            </plane>
          </geometry>
          <surface>
            <friction>
              <ode/>
            </friction>
          </surface>
        </collision>
        <visual name='visual'>
          <geometry>
            <plane>
              <normal>0 0 1</normal>
              <size>100 100</size>
            </plane>
          </geometry>
          <material>
            <ambient>0.800000012 0.800000012 0.800000012 1</ambient>
            <diffuse>0.800000012 0.800000012 0.800000012 1</diffuse>
          </material>
        </visual>
      </link>
    </model>

    <model name='crawler_robot'>
      <pose>0 0 0.15 0 0 0</pose>
      
      <link name='base_link'>
        <inertial>
          <mass>1</mass>
          <inertia>
            <ixx>0.1</ixx> <ixy>0</ixy> <ixz>0</ixz>
            <iyy>0.1</iyy> <iyz>0</iyz> <izz>0.1</izz>
          </inertia>
        </inertial>
        <visual name='base_visual'>
          <geometry>
            <box>
              <size>0.25 0.3 0.1</size>
            </box>
          </geometry>
          <material>
            <ambient>0.3 0.3 0.3 1</ambient>
            <diffuse>0.3 0.3 0.3 1</diffuse>
          </material>
        </visual>
        <collision name='base_collision'>
          <geometry>
            <box>
              <size>0.25 0.3 0.1</size>
            </box>
          </geometry>
        </collision>

        <sensor name='imu_sensor' type='imu'>
          <topic>/imu_data</topic>
          <update_rate>100</update_rate>
          <imu>
            <enable_orientation>true</enable_orientation>
          </imu>
        </sensor>

        <sensor name='gpu_lidar' type='gpu_lidar'>
          <pose>0 0 0.08 0 0 0</pose>
          <topic>lidar</topic>
          <update_rate>10</update_rate>
          <lidar>
            <scan>
              <horizontal>
                <samples>640</samples>
                <resolution>1</resolution>
                <min_angle>-3.141592</min_angle>
                <max_angle>3.141592</max_angle>
              </horizontal>
            </scan>
            <range>
              <min>0.08</min> <max>10</max>
            </range>
          </lidar>
        </sensor>

        <sensor name="camera" type="camera">
           <pose>0 0 0 0 0 3.141592</pose>
           <topic>/camera/image</topic>

           <always_on>true</always_on>
           <update_rate>30</update_rate>
           <visualize>true</visualize>
           <camera>
             <horizontal_fov>1.2</horizontal_fov>
             <image>
               <format>R8G8B8</format>
               <width>800</width>
               <height>800</height>
             </image>
             <clip>
               <near>0.02</near>
               <far>300</far>
             </clip>
           </camera>
        </sensor>

        <sensor name="camera2" type="camera">
           <pose>0 0 0 0 0 0</pose>
           <topic>/camera2/image</topic>

           <always_on>true</always_on>
           <update_rate>30</update_rate>
           <visualize>true</visualize>
           <camera>
             <horizontal_fov>1.2</horizontal_fov>
             <image>
               <format>R8G8B8</format>
               <width>800</width>
               <height>800</height>
             </image>
             <clip>
               <near>0.02</near>
               <far>300</far>
             </clip>
           </camera>
        </sensor>
      </link>

      <frame name='lidar_frame' attached_to='base_link'>
        <pose>0 0 0.08 0 0 0</pose>
      </frame>

      <frame name='depth_frame' attached_to='base_link'>
        <pose>0 0 0.08 0 0.001 0</pose>
      </frame>

      <link name='crawler_right_visual'>
        <pose>-0.26 0.24 -0.1 0 0 0</pose>
        <visual name='visual'>
          <geometry>
            <mesh>
              <uri>file:///home/ubuntu/projects/slam/crawler.stl</uri>
              <scale>0.001 0.001 0.001</scale>
            </mesh>
          </geometry>
          <material>
            <ambient>0.3 0.3 0.3 1</ambient>
            <diffuse>0.3 0.3 0.3 1</diffuse>
          </material>
        </visual>
        <inertial>
           <mass>0.1</mass>
           <inertia>
             <ixx>0.01</ixx> <iyy>0.01</iyy> <izz>0.01</izz>
           </inertia>
        </inertial>
      </link>

      <link name='crawler_left_visual'>
        <pose>-0.26 -0.15 -0.1 0 0 0</pose>
        <visual name='visual'>
          <geometry>
            <mesh>
              <uri>file:///home/ubuntu/projects/slam/crawler.stl</uri>
              <scale>0.001 0.001 0.001</scale>
            </mesh>
          </geometry>
          <material>
            <ambient>0.3 0.3 0.3 1</ambient>
            <diffuse>0.3 0.3 0.3 1</diffuse>
          </material>
        </visual>
        <inertial>
           <mass>0.1</mass>
           <inertia>
             <ixx>0.01</ixx> <iyy>0.01</iyy> <izz>0.01</izz>
           </inertia>
        </inertial>
      </link>

      <joint name='fixed_right_visual' type='fixed'>
        <parent>base_link</parent>
        <child>crawler_right_visual</child>
      </joint>
      <joint name='fixed_left_visual' type='fixed'>
        <parent>base_link</parent>
        <child>crawler_left_visual</child>
      </joint>

      <link name='right_wheel_1'>
        <pose>0.1 0.2 -0.04 -1.5707 0 0</pose> <inertial>
          <mass>0.2</mass>
          <inertia>
            <ixx>0.01</ixx> <iyy>0.01</iyy> <izz>0.01</izz>
            <ixy>0</ixy> <ixz>0</ixz> <iyz>0</iyz>
          </inertia>
        </inertial>
        <collision name='col'>
          <geometry>
            <cylinder>
              <radius>0.06</radius> <length>0.05</length>
            </cylinder>
          </geometry>
          <surface>
            <friction>
              <ode>
                <mu>1.0</mu> <mu2>1.0</mu2>
              </ode>
            </friction>
          </surface>
        </collision>
        <visual name='vis'>
          <geometry>
            <cylinder>
              <radius>0.06</radius> <length>0.05</length>
            </cylinder>
          </geometry>
          <material>
            <ambient>1 0 0 0.5</ambient>
            <diffuse>1 0 0 0.5</diffuse>
          </material>
        </visual>
      </link>

      <joint name='right_wheel_joint1' type='revolute'>
        <parent>base_link</parent>
        <child>right_wheel_1</child>
        <axis>
          <xyz>0 0 1</xyz>
        </axis>
      </joint>

      <link name='right_roller_1'>
        <pose>0.025 0.2 -0.07 -1.5707 0 0</pose> <inertial>
          <mass>0.1</mass>
          <inertia>
            <ixx>0.001</ixx> <iyy>0.001</iyy> <izz>0.001</izz>
          </inertia>
        </inertial>
        <collision name='col'>
          <geometry>
            <cylinder>
              <radius>0.03</radius> <length>0.05</length>
            </cylinder>
          </geometry>
          <surface>
            <friction>
              <ode>
                <mu>0.5</mu> <mu2>0.1</mu2> </ode>
            </friction>
          </surface>
        </collision>
        <visual name='vis'>
          <geometry>
            <cylinder>
              <radius>0.03</radius> <length>0.05</length>
            </cylinder>
          </geometry>
          <material>
            <ambient>0 0 1 0.5</ambient>
            <diffuse>0 0 1 0.5</diffuse>
          </material>
        </visual>
      </link>
      <joint name='right_roller_joint1' type='revolute'>
        <parent>base_link</parent>
        <child>right_roller_1</child>
        <axis>
          <xyz>0 0 1</xyz>
          <dynamics><friction>0.01</friction></dynamics>
        </axis>
      </joint>

      <link name='right_roller_2'>
        <pose>-0.05 0.2 -0.07 -1.5707 0 0</pose>
        <inertial>
          <mass>0.1</mass>
          <inertia>
            <ixx>0.001</ixx> <iyy>0.001</iyy> <izz>0.001</izz>
          </inertia>
        </inertial>
        <collision name='col'>
          <geometry>
            <cylinder>
              <radius>0.03</radius> <length>0.05</length>
            </cylinder>
          </geometry>
          <surface>
            <friction>
              <ode>
                <mu>0.5</mu> <mu2>0.1</mu2>
              </ode>
            </friction>
          </surface>
        </collision>
        <visual name='vis'>
          <geometry>
            <cylinder>
              <radius>0.03</radius> <length>0.05</length>
            </cylinder>
          </geometry>
          <material>
            <ambient>0 0 1 0.5</ambient>
            <diffuse>0 0 1 0.5</diffuse>
          </material>
        </visual>
      </link>
      <joint name='right_roller_joint2' type='revolute'>
        <parent>base_link</parent>
        <child>right_roller_2</child>
        <axis>
          <xyz>0 0 1</xyz>
          <dynamics><friction>0.01</friction></dynamics>
        </axis>
      </joint>

      <link name='right_roller_3'>
        <pose>-0.125 0.2 -0.07 -1.5707 0 0</pose>
        <inertial>
          <mass>0.1</mass>
          <inertia>
            <ixx>0.001</ixx> <iyy>0.001</iyy> <izz>0.001</izz>
          </inertia>
        </inertial>
        <collision name='col'>
          <geometry>
            <cylinder>
              <radius>0.03</radius> <length>0.05</length>
            </cylinder>
          </geometry>
          <surface>
            <friction>
              <ode>
                <mu>0.5</mu> <mu2>0.1</mu2>
              </ode>
            </friction>
          </surface>
        </collision>
        <visual name='vis'>
          <geometry>
            <cylinder>
              <radius>0.03</radius> <length>0.05</length>
            </cylinder>
          </geometry>
          <material>
            <ambient>0 0 1 0.5</ambient>
            <diffuse>0 0 1 0.5</diffuse>
          </material>
        </visual>
      </link>
      <joint name='right_roller_joint3' type='revolute'>
        <parent>base_link</parent>
        <child>right_roller_3</child>
        <axis>
          <xyz>0 0 1</xyz>
          <dynamics><friction>0.01</friction></dynamics>
        </axis>
      </joint>

      <link name='right_wheel_4'>
        <pose>-0.2 0.2 -0.04 -1.5707 0 0</pose>
        <inertial>
          <mass>0.2</mass>
          <inertia>
            <ixx>0.01</ixx> <iyy>0.01</iyy> <izz>0.01</izz>
          </inertia>
        </inertial>
        <collision name='col'>
          <geometry>
            <cylinder>
              <radius>0.06</radius> <length>0.05</length>
            </cylinder>
          </geometry>
          <surface>
            <friction>
              <ode>
                <mu>1.0</mu> <mu2>1.0</mu2>
              </ode>
            </friction>
          </surface>
        </collision>
        <visual name='vis'>
          <geometry>
            <cylinder>
              <radius>0.06</radius> <length>0.05</length>
            </cylinder>
          </geometry>
          <material>
            <ambient>1 0 0 0.5</ambient>
            <diffuse>1 0 0 0.5</diffuse>
          </material>
        </visual>
      </link>
      <joint name='right_wheel_joint4' type='revolute'>
        <parent>base_link</parent>
        <child>right_wheel_4</child>
        <axis>
          <xyz>0 0 1</xyz>
        </axis>
      </joint>

      <link name='left_wheel_1'>
        <pose>0.1 -0.2 -0.04 -1.5707 0 0</pose>
        <inertial>
          <mass>0.2</mass>
          <inertia>
            <ixx>0.01</ixx> <iyy>0.01</iyy> <izz>0.01</izz>
            <ixy>0</ixy> <ixz>0</ixz> <iyz>0</iyz>
          </inertia>
        </inertial>
        <collision name='col'>
          <geometry>
            <cylinder>
              <radius>0.06</radius> <length>0.05</length>
            </cylinder>
          </geometry>
          <surface>
            <friction>
              <ode>
                <mu>1.0</mu> <mu2>1.0</mu2>
              </ode>
            </friction>
          </surface>
        </collision>
        <visual name='vis'>
          <geometry>
            <cylinder>
              <radius>0.06</radius> <length>0.05</length>
            </cylinder>
          </geometry>
          <material>
            <ambient>1 0 0 0.5</ambient>
            <diffuse>1 0 0 0.5</diffuse>
          </material>
        </visual>
      </link>
      <joint name='left_wheel_joint1' type='revolute'>
        <parent>base_link</parent>
        <child>left_wheel_1</child>
        <axis>
          <xyz>0 0 1</xyz>
        </axis>
      </joint>

      <link name='left_roller_1'>
        <pose>0.025 -0.2 -0.07 -1.5707 0 0</pose>
        <inertial>
          <mass>0.1</mass>
          <inertia>
            <ixx>0.001</ixx> <iyy>0.001</iyy> <izz>0.001</izz>
          </inertia>
        </inertial>
        <collision name='col'>
          <geometry>
            <cylinder>
              <radius>0.03</radius> <length>0.05</length>
            </cylinder>
          </geometry>
          <surface>
            <friction>
              <ode>
                <mu>0.5</mu> <mu2>0.1</mu2>
              </ode>
            </friction>
          </surface>
        </collision>
        <visual name='vis'>
          <geometry>
            <cylinder>
              <radius>0.03</radius> <length>0.05</length>
            </cylinder>
          </geometry>
          <material>
            <ambient>0 0 1 0.5</ambient>
            <diffuse>0 0 1 0.5</diffuse>
          </material>
        </visual>
      </link>
      <joint name='left_roller_joint1' type='revolute'>
        <parent>base_link</parent>
        <child>left_roller_1</child>
        <axis>
          <xyz>0 0 1</xyz>
          <dynamics><friction>0.01</friction></dynamics>
        </axis>
      </joint>

      <link name='left_roller_2'>
        <pose>-0.05 -0.2 -0.07 -1.5707 0 0</pose>
        <inertial>
          <mass>0.1</mass>
          <inertia>
            <ixx>0.001</ixx> <iyy>0.001</iyy> <izz>0.001</izz>
          </inertia>
        </inertial>
        <collision name='col'>
          <geometry>
            <cylinder>
              <radius>0.03</radius> <length>0.05</length>
            </cylinder>
          </geometry>
          <surface>
            <friction>
              <ode>
                <mu>0.5</mu> <mu2>0.1</mu2>
              </ode>
            </friction>
          </surface>
        </collision>
        <visual name='vis'>
          <geometry>
            <cylinder>
              <radius>0.03</radius> <length>0.05</length>
            </cylinder>
          </geometry>
          <material>
            <ambient>0 0 1 0.5</ambient>
            <diffuse>0 0 1 0.5</diffuse>
          </material>
        </visual>
      </link>
      <joint name='left_roller_joint2' type='revolute'>
        <parent>base_link</parent>
        <child>left_roller_2</child>
        <axis>
          <xyz>0 0 1</xyz>
          <dynamics><friction>0.01</friction></dynamics>
        </axis>
      </joint>

      <link name='left_roller_3'>
        <pose>-0.125 -0.2 -0.07 -1.5707 0 0</pose>
        <inertial>
          <mass>0.1</mass>
          <inertia>
            <ixx>0.001</ixx> <iyy>0.001</iyy> <izz>0.001</izz>
          </inertia>
        </inertial>
        <collision name='col'>
          <geometry>
            <cylinder>
              <radius>0.03</radius> <length>0.05</length>
            </cylinder>
          </geometry>
          <surface>
            <friction>
              <ode>
                <mu>0.5</mu> <mu2>0.1</mu2>
              </ode>
            </friction>
          </surface>
        </collision>
        <visual name='vis'>
          <geometry>
            <cylinder>
              <radius>0.03</radius> <length>0.05</length>
            </cylinder>
          </geometry>
          <material>
            <ambient>0 0 1 0.5</ambient>
            <diffuse>0 0 1 0.5</diffuse>
          </material>
        </visual>
      </link>
      <joint name='left_roller_joint3' type='revolute'>
        <parent>base_link</parent>
        <child>left_roller_3</child>
        <axis>
          <xyz>0 0 1</xyz>
          <dynamics><friction>0.01</friction></dynamics>
        </axis>
      </joint>

      <link name='left_wheel_4'>
        <pose>-0.2 -0.2 -0.04 -1.5707 0 0</pose>
        <inertial>
          <mass>0.2</mass>
          <inertia>
            <ixx>0.01</ixx> <iyy>0.01</iyy> <izz>0.01</izz>
            <ixy>0</ixy> <ixz>0</ixz> <iyz>0</iyz>
          </inertia>
        </inertial>
        <collision name='col'>
          <geometry>
            <cylinder>
              <radius>0.06</radius> <length>0.05</length>
            </cylinder>
          </geometry>
          <surface>
            <friction>
              <ode>
                <mu>1.0</mu> <mu2>1.0</mu2>
              </ode>
            </friction>
          </surface>
        </collision>
        <visual name='vis'>
          <geometry>
            <cylinder>
              <radius>0.06</radius> <length>0.05</length>
            </cylinder>
          </geometry>
          <material>
            <ambient>1 0 0 0.5</ambient>
            <diffuse>1 0 0 0.5</diffuse>
          </material>
        </visual>
      </link>
      <joint name='left_wheel_joint4' type='revolute'>
        <parent>base_link</parent>
        <child>left_wheel_4</child>
        <axis>
          <xyz>0 0 1</xyz>
        </axis>
      </joint>

      <plugin name='gz::sim::systems::Sensors' filename='gz-sim-sensors-system'>
        <render_engine>ogre2</render_engine>
      </plugin>

      <plugin filename="gz-sim-imu-system"
              name="gz::sim::systems::Imu">
      </plugin>

      <static>false</static>
      <self_collide>false</self_collide>

      <plugin filename="gz-sim-diff-drive-system" name="gz::sim::systems::DiffDrive">
          <left_joint>left_wheel_joint1</left_joint>
          <left_joint>left_wheel_joint4</left_joint>
      
          <right_joint>right_wheel_joint1</right_joint>
          <right_joint>right_wheel_joint4</right_joint>
      
          <wheel_separation>0.4</wheel_separation> 
          <wheel_radius>0.06</wheel_radius>
          
          <max_linear_acceleration>1</max_linear_acceleration>
          <min_linear_acceleration>-1</min_linear_acceleration>
          <max_angular_acceleration>2</max_angular_acceleration>
          <min_angular_acceleration>-2</min_angular_acceleration>
          <max_linear_velocity>1.0</max_linear_velocity>
          <min_linear_velocity>-1.0</min_linear_velocity>
      
          <topic>/cmd_vel</topic>
          <odom_topic>odom</odom_topic>
          <tf_topic>tf</tf_topic>
          <frame_id>odom</frame_id>
          <child_frame_id>base_link</child_frame_id>
      </plugin>
    </model>

    <model name='box'>
      <pose>0.0765 1.028 0 0 0 0</pose>
      <link name='box_link'>
        <inertial>
          <inertia>
            <ixx>0.166</ixx> <iyy>0.166</iyy> <izz>0.166</izz>
            <ixy>0</ixy> <ixz>0</ixz> <iyz>0</iyz>
          </inertia>
          <mass>10</mass>
        </inertial>
        <collision name='box_collision'>
          <geometry>
            <box> <size>1 1 0.1</size> </box>
          </geometry>
        </collision>
        <visual name='box_visual'>
          <geometry>
            <box> <size>1 1 0.1</size> </box>
          </geometry>
          <material>
            <ambient>0.3 0.3 0.3 1</ambient>
            <diffuse>0.7 0.7 0.7 1</diffuse>
          </material>
        </visual>
      </link>
    </model>

    <model name='box_0'>
      <pose>1.15 -0.26 0.5 0 0 0</pose>
      <link name='box_link'>
        <inertial>
          <inertia>
            <ixx>0.166</ixx> <iyy>0.166</iyy> <izz>0.166</izz>
            <ixy>0</ixy> <ixz>0</ixz> <iyz>0</iyz>
          </inertia>
          <mass>1</mass>
        </inertial>
        <collision name='box_collision'>
          <geometry>
            <box> <size>1 1 1</size> </box>
          </geometry>
        </collision>
        <visual name='box_visual'>
          <geometry>
            <box> <size>1 1 1</size> </box>
          </geometry>
          <material>
            <ambient>0.3 0.3 0.3 1</ambient>
            <diffuse>0.7 0.7 0.7 1</diffuse>
          </material>
        </visual>
      </link>
    </model>

    <model name='box_1'>
      <pose>-0.14 -1.0 0.5 0 0 0</pose>
      <link name='box_link'>
        <inertial>
          <inertia>
            <ixx>0.166</ixx> <iyy>0.166</iyy> <izz>0.166</izz>
            <ixy>0</ixy> <ixz>0</ixz> <iyz>0</iyz>
          </inertia>
          <mass>1</mass>
        </inertial>
        <collision name='box_collision'>
          <geometry>
            <box> <size>1 1 1</size> </box>
          </geometry>
        </collision>
        <visual name='box_visual'>
          <geometry>
            <box> <size>1 1 1</size> </box>
          </geometry>
          <material>
            <ambient>0.3 0.3 0.3 1</ambient>
            <diffuse>0.7 0.7 0.7 1</diffuse>
          </material>
        </visual>
      </link>
    </model>

    <light name='sun' type='directional'>
      <pose>0 0 10 0 0 0</pose>
      <cast_shadows>true</cast_shadows>
      <intensity>1</intensity>
      <direction>-0.5 0.1 -0.9</direction>
      <diffuse>0.8 0.8 0.8 1</diffuse>
      <specular>0.2 0.2 0.2 1</specular>
    </light>

  </world>
</sdf>
